Workbook

Sheet Program
A1: Short Code | B1: Code | C1: Description | D1: Program Coordinator | F1: Academic Year | H1: Semester | J1: Description
A2: CS | B2: 010I61 | C2: Master of Engineering – M.E in Computer Science and Engineering | D2: SNM | F2: 2026-2027 | H2: Semester - I | J2: =IF(Setup!$B$1="","",IF(Setup!$B$2="Invalid Faculty Code","Enter Valid Faculty Code",IF(C2="","",C2))) -> Master of Engineering – M.E in Computer Science and Engineering
A3: ESD | B3: 010I62 | C3: Master of Engineering - M.E in Computer Science and Engineering (Embedded Systems) | D3: BDR | F3: 2027-2028 | H3: Semester - II | J3: =IF(Setup!$B$1="","",IF(Setup!$B$2="Invalid Faculty Code","",IF(C3="","",C3))) -> Master of Engineering - M.E in Computer Science and Engineering (Embedded Systems)
A4: MVT | B4: 010I63 | C4: Master of Engineering - M.E in Electronics Engineering (Microelectronics and VLSI Technology) | D4: RM | F4: 2028-2029 | J4: =IF(Setup!$B$1="","",IF(Setup!$B$2="Invalid Faculty Code","",IF(C4="","",C4))) -> Master of Engineering - M.E in Electronics Engineering (Microelectronics and VLSI Technology)
A5: VLSI | B5: 010I64 | C5: Master of Engineering - M.E in Electronics Engineering (VLSI Design) | D5: MS | F5: 2029-2030 | J5: =IF(Setup!$B$1="","",IF(Setup!$B$2="Invalid Faculty Code","",IF(C5="","",C5))) -> Master of Engineering - M.E in Electronics Engineering (VLSI Design)
A6: AES | B6: 010I65 | C6: Master of Engineering - M.E in Computer Science and Engineering (Embedded Systems, Dual Degree Program with ESIGELEC, France) | D6: BDR | F6: 2030-2031 | J6: =IF(Setup!$B$1="","",IF(Setup!$B$2="Invalid Faculty Code","",IF(C6="","",C6))) -> Master of Engineering - M.E in Computer Science and Engineering (Embedded Systems, Dual Degree Program with ESIGELEC, France)
A7: AIML | B7: 010I66 | C7: Master of Engineering - M.E in Computer Science and Engineering (Artificial Intelligence and Machine Learning) | D7: RS | F7: 2031-2032 | J7: =IF(Setup!$B$1="","",IF(Setup!$B$2="Invalid Faculty Code","",IF(C7="","",C7))) -> Master of Engineering - M.E in Computer Science and Engineering (Artificial Intelligence and Machine Learning)
A8: BDA | B8: 010I67 | C8: Master of Engineering - M.E in Computer Science and Engineering (Big Data Analytics) | D8: RS | F8: 2032-2033 | J8: =IF(Setup!$B$1="","",IF(Setup!$B$2="Invalid Faculty Code","",IF(C8="","",C8))) -> Master of Engineering - M.E in Computer Science and Engineering (Big Data Analytics)
A9: CDC | B9: 010I68 | C9: Master of Engineering - M.E in Computer Science and Engineering (Cloud Computing) | D9: PRN | J9: =IF(Setup!$B$1="","",IF(Setup!$B$2="Invalid Faculty Code","",IF(C9="","",C9))) -> Master of Engineering - M.E in Computer Science and Engineering (Cloud Computing)
A10: CYS | B10: 010I69 | C10: Master of Engineering - M.E in Computer Science and Engineering (Cyber Security) | D10: KB | J10: =IF(Setup!$B$1="","",IF(Setup!$B$2="Invalid Faculty Code","",IF(C10="","",C10))) -> Master of Engineering - M.E in Computer Science and Engineering (Cyber Security)
J11: =IF(Setup!$B$1="","",IF(Setup!$B$2="Invalid Faculty Code","",IF(C11="","",C11)))
J12: =IF(Setup!$B$1="","",IF(Setup!$B$2="Invalid Faculty Code","",IF(C12="","",C12)))
J13: =IF(Setup!$B$1="","",IF(Setup!$B$2="Invalid Faculty Code","",IF(C13="","",C13)))
J14: =IF(Setup!$B$1="","",IF(Setup!$B$2="Invalid Faculty Code","",IF(C14="","",C14)))
J15: =IF(Setup!$B$1="","",IF(Setup!$B$2="Invalid Faculty Code","",IF(C15="","",C15)))
J16: =IF(Setup!$B$1="","",IF(Setup!$B$2="Invalid Faculty Code","",IF(C16="","",C16)))
J17: =IF(Setup!$B$1="","",IF(Setup!$B$2="Invalid Faculty Code","",IF(C17="","",C17)))
J18: =IF(Setup!$B$1="","",IF(Setup!$B$2="Invalid Faculty Code","",IF(C18="","",C18)))
J19: =IF(Setup!$B$1="","",IF(Setup!$B$2="Invalid Faculty Code","",IF(C19="","",C19)))
J20: =IF(Setup!$B$1="","",IF(Setup!$B$2="Invalid Faculty Code","",IF(C20="","",C20)))

Sheet Course
A1: Program Code | B1: Semester | C1: Course Code | D1: Course Name | E1: PO1 | F1: PO2 | G1: PO3 | H1: PO4 | I1: PO5 | J1: Sort No | K1: Short Code | L1: Subject Type | M1: Subject Class | N1: Status | P1: Active Subject | R1: PO for Mapping
A2: 010I61 | B2: I | C2: AME 5002 | D2: Applied Machine Learning | E2: * | G2: * | H2: * | J2: 1 | K2: AML | L2: Theory | M2: Core | N2: =IF(K2="","","Active") -> Active | P2: Subject Code | Q2: {=TRANSPOSE(_xlfn._xlws.FILTER($C$2:$I$600,($L$2:$L$600="Theory")*($N$2:$N$600="Active")*($A$2:$A$600=Setup!$B$7)*($C$2:$C$600=Setup!$B$8),""))} -> AME 5101
A3: 010I61 | B3: I | C3: AME 5101 | D3: Applied Linear Algebra | G3: * | H3: * | J3: 2 | K3: ALA | L3: Theory | M3: Core | N3: =IF(K3="","","Active") -> Active | P3: Subject Name | Q3: Applied Linear Algebra
A4: 010I61 | B4: I | C4: CCE 5101 | D4: Cloud Application with JAVA and Database with Java | G4: * | H4: * | I4: * | J4: 3 | K4: CAJ | L4: Theory | M4: Core | N4: =IF(K4="","","Active") -> Active | P4: PO1 | R4: {=_xlfn._xlws.FILTER($P$4:$P$8,$Q$4:$Q$8="*","")} -> PO3
A5: 010I61 | B5: I | C5: ESE 5102 | D5: Data Structures and Algorithms | G5: * | H5: * | I5: * | J5: 4 | K5: DSA | L5: Theory | M5: Core | N5: =IF(K5="","","Active") -> Active | P5: PO2 | R5: PO4
A6: 010I61 | B6: I | C6: ESE 5104 | D6: Real Time Operating Systems | G6: * | H6: * | I6: * | J6: 5 | K6: RTOS | L6: Theory | M6: Core | N6: =IF(K6="","","Active") -> Active | P6: PO3 | Q6: *
A7: 010I61 | B7: I | C7: AME 5052 | D7: Applied Machine Learning Lab | E7: * | G7: * | H7: * | J7: 6 | K7: AML Lab | L7: Lab | M7: Core | N7: =IF(K7="","","Active") -> Active | P7: PO4 | Q7: *
A8: 010I61 | B8: I | C8: AME 5151 | D8: Applied Linear Algebra Lab | G8: * | I8: * | J8: 7 | K8: ALA Lab | L8: Lab | M8: Core | N8: =IF(K8="","","Active") -> Active | P8: PO5
A9: 010I61 | B9: I | C9: CCE 5151 | D9: Cloud Application with JAVA and Database with Java Lab | G9: * | H9: * | I9: * | J9: 8 | K9: CAJ Lab | L9: Lab | M9: Core | N9: =IF(K9="","","Active") -> Active
A10: 010I61 | B10: I | C10: ESE 5152 | D10: Data Structures and Algorithms Lab | G10: * | H10: * | I10: * | J10: 9 | K10: DSA Lab | L10: Lab | M10: Core | N10: =IF(K10="","","Active") -> Active
A11: 010I61 | B11: I | C11: ESE 5154 | D11: Real Time Operating Systems Lab | G11: * | H11: * | I11: * | J11: 10 | K11: RTOS Lab | L11: Lab | M11: Core | N11: =IF(K11="","","Active") -> Active
A12: 010I61 | B12: I | C12: MPT 5100 | D12: Mini Project - I | E12: * | F12: * | G12: * | H12: * | I12: * | J12: 11 | K12: MP 1 | L12: Project | M12: Core | N12: =IF(K12="","","Active") -> Active
A13: 010I61 | B13: I | C13: PSD 5100 | D13: Professional Skill Development - I | E13: * | F13: * | J13: 12 | K13: PDS 1 | L13: Seminar | M13: Core | N13: =IF(K13="","","Active") -> Active
A14: 010I61 | B14: II | C14: AME 5202 | D14: Deep Learning | E14: * | G14: * | H14: * | J14: 13 | L14: Theory | M14: Core | N14: =IF(K14="","","Active")
A15: 010I61 | B15: II | C15: BDE 5202 | D15: Modern Databases for Big Data | E15: * | H15: * | J15: 14 | L15: Theory | M15: Core | N15: =IF(K15="","","Active") | Q15: Available Subject
A16: 010I61 | B16: II | C16: ESE 5201 | D16: Device Drivers | G16: * | I16: * | J16: 15 | L16: Theory | M16: Core | N16: =IF(K16="","","Active") | Q16: {=IF(Setup!B2="","Faculty Details Missing",_xlfn._xlws.FILTER($D$2:$D$600,($L$2:$L$600="Theory")*($N$2:$N$600="Active")*($A$2:$A$600=Setup!$B$7)*($B$2:$B$600=Setup!$B$12),""))} -> Applied Machine Learning
A17: 010I61 | B17: II | C17: AME 5204 | D17: Applied Computer Vision | G17: * | H17: * | J17: 16 | L17: Theory | M17: Ele 1 | N17: =IF(K17="","","Active") | Q17: Applied Linear Algebra
A18: 010I61 | B18: II | C18: BDE 5203 | D18: Data Engineering | E18: * | H18: * | J18: 17 | L18: Theory | M18: Ele 1 | N18: =IF(K18="","","Active") | Q18: Cloud Application with JAVA and Database with Java
A19: 010I61 | B19: II | C19: CCE 5001 | D19: DevOps for Cloud | G19: * | H19: * | I19: * | J19: 18 | L19: Theory | M19: Ele 1 | N19: =IF(K19="","","Active") | Q19: Data Structures and Algorithms
A20: 010I61 | B20: II | C20: CCE 5203 | D20: Cloud Security Essentials | G20: * | H20: * | I20: * | J20: 19 | L20: Theory | M20: Ele 1 | N20: =IF(K20="","","Active") | Q20: Real Time Operating Systems
A21: 010I61 | B21: II | C21: CYE 5202 | D21: Web Security and Secure Coding | E21: * | F21: * | I21: * | J21: 20 | L21: Theory | M21: Ele 1 | N21: =IF(K21="","","Active")
A22: 010I61 | B22: II | C22: ESE 5234 | D22: Entrepreneurship | G22: * | H22: * | J22: 21 | L22: Theory | M22: Ele 1 | N22: =IF(K22="","","Active")
A23: 010I61 | B23: II | C23: AME 5003 | D23: Principles of Natural Language Processing | G23: * | H23: * | J23: 22 | L23: Theory | M23: Ele 2 | N23: =IF(K23="","","Active")
A24: 010I61 | B24: II | C24: AME 5205 | D24: Advanced Generative AI and Agentic Systems | E24: * | G24: * | H24: * | J24: 23 | L24: Theory | M24: Ele 2 | N24: =IF(K24="","","Active")
A25: 010I61 | B25: II | C25: CCE 5241 | D25: Cloud Operations | G25: * | H25: * | I25: * | J25: 24 | L25: Theory | M25: Ele 2 | N25: =IF(K25="","","Active")
A26: 010I61 | B26: II | C26: CYE 5203 | D26: Machine Learning for Cybersecurity | G26: * | H26: * | J26: 25 | L26: Theory | M26: Ele 2 | N26: =IF(K26="","","Active")
A27: 010I61 | B27: II | C27: ESE 5244 | D27: IT Project Management | G27: * | H27: * | J27: 26 | L27: Theory | M27: Ele 2 | N27: =IF(K27="","","Active")
A28: 010I61 | B28: II | C28: AME 5252 | D28: Deep Learning Lab | E28: * | I28: * | J28: 27 | L28: Lab | M28: Core | N28: =IF(K28="","","Active")
A29: 010I61 | B29: II | C29: BDE 5252 | D29: Modern Databases for Big Data Lab | E29: * | H29: * | I29: * | J29: 28 | L29: Lab | M29: Core | N29: =IF(K29="","","Active")
A30: 010I61 | B30: II | C30: ESE 5251 | D30: Device Drivers Lab | G30: * | I30: * | J30: 29 | L30: Lab | M30: Core | N30: =IF(K30="","","Active")
A31: 010I61 | B31: II | C31: AME 5254 | D31: Applied Computer Vision Lab | G31: * | H31: * | I31: * | J31: 30 | L31: Lab | M31: Ele 1 | N31: =IF(K31="","","Active")
A32: 010I61 | B32: II | C32: BDE 5253 | D32: Data Engineering Lab | G32: * | I32: * | J32: 31 | L32: Lab | M32: Ele 1 | N32: =IF(K32="","","Active")
A33: 010I61 | B33: II | C33: CCE 5051 | D33: DevOps for Cloud Lab | G33: * | H33: * | I33: * | J33: 32 | L33: Lab | M33: Ele 1 | N33: =IF(K33="","","Active")
A34: 010I61 | B34: II | C34: CCE 5253 | D34: Cloud Security Essentials Lab | G34: * | H34: * | I34: * | J34: 33 | L34: Lab | M34: Ele 1 | N34: =IF(K34="","","Active")
A35: 010I61 | B35: II | C35: CYE 5252 | D35: Web Security and Secure Coding Lab | E35: * | F35: * | I35: * | J35: 34 | L35: Lab | M35: Ele 1 | N35: =IF(K35="","","Active")
A36: 010I61 | B36: II | C36: ESE 5284 | D36: Entrepreneurship Lab | G36: * | H36: * | J36: 35 | L36: Lab | M36: Ele 1 | N36: =IF(K36="","","Active")
A37: 010I61 | B37: II | C37: AME 5053 | D37: Principles of Natural Language Processing Lab | G37: * | I37: * | J37: 36 | L37: Lab | M37: Ele 2 | N37: =IF(K37="","","Active")
A38: 010I61 | B38: II | C38: AME 5255 | D38: Advanced Generative AI and Agentic Systems Lab | G38: * | H38: * | I38: * | J38: 37 | L38: Lab | M38: Ele 2 | N38: =IF(K38="","","Active")
A39: 010I61 | B39: II | C39: CCE 5291 | D39: Cloud Operations Lab | G39: * | H39: * | I39: * | J39: 38 | L39: Lab | M39: Ele 2 | N39: =IF(K39="","","Active")
A40: 010I61 | B40: II | C40: CYE 5253 | D40: Machine Learning for Cybersecurity Lab | G40: * | H40: * | I40: * | J40: 39 | L40: Lab | M40: Ele 2 | N40: =IF(K40="","","Active")
...

Sheet PEOs
A1: PEO Master | E1: Selected PEO
A2: Program | B2: PEO | C2: Description | E2: PEO | F2: Description
A3: 010I38 | B3: PEO 1 | C3: Successfully engage in challenging careers with professional approach in the areas of analog and digital VLSI design and related domains of engineering. | E3: {=_xlfn._xlws.FILTER($B$3:$C$100,$A$3:$A$100=Setup!$B$7,"")} -> PEO 1 | F3: Enable to draw upon fundamental and advanced knowledge to apply analytical and computational approaches to solve technological problems in computer science.
A4: 010I38 | B4: PEO 2 | C4: Demonstrate competence in identifying and analysing technical problems, suggest feasible and innovative solutions using their core competence in VLSI design and thereby support the technological growth of the nation. | E4: PEO 2 | F4: Introduce state of art technologies in computer science and inculcate ethical practices to make industry-ready professionals.
A5: 010I38 | B5: PEO 3 | C5: Impart quality technical education, engage in research and contribute to knowledge creation and sharing. | E5: PEO 3 | F5: Promote scientific and societal advancement through research and entrepreneurship.
A6: 010I38 | B6: PEO 4 | C6: Possess analytical, communicative and leadership skills, and demonstrate the ability to work in multidisciplinary and multi-cultural environments.
A7: 010I38 | B7: PEO 5 | C7: Be self-motivated and remain continuously employable by engaging in lifelong learning.
A8: 010I39 | B8: PEO 1 | C8: Enable to draw upon fundamental and advanced knowledge to apply analytical and computational approaches to solve technological problems in embedded systems.
A9: 010I39 | B9: PEO 2 | C9: Introduce state of art technologies in the area of embedded systems and inculcate ethical practices to make industry-ready professionals.
A10: 010I39 | B10: PEO 3 | C10: Promote scientific and societal advancement through research and entrepreneurship.
A11: 010I47 | B11: PEO 1 | C11: Develop advanced knowledge and understanding of the theories, concepts, and principles related to Cloud Computing, including virtualization, distributed systems, cloud networks, security, microservices, and cloud infrastructure management services.
A12: 010I47 | B12: PEO 2 | C12: Apply critical thinking and problem-solving skills to address complex challenges in cloud computing such as scalability, resource scheduling, performance optimization and data management.
A13: 010I47 | B13: PEO 3 | C13: Gain practical, hands-on experience with global cloud provider services, DevOps tools, automation and container orchestration services through coursework and applied research experiences.
A14: 010I57 | B14: PEO 1 | C14: Acquire solid mathematical and computational skills essential for understanding, applying, and developing modern artificial intelligence and machine learning algorithms.
A15: 010I57 | B15: PEO 2 | C15: Produce industry-ready graduates with practical experience in structuring machine learning projects using state-of-the-art software.
A16: 010I57 | B16: PEO 3 | C16: Address multi-disciplinary challenges through coursework and projects by adapting to the rapidly advancing developments in artificial intelligence and machine learning approaches.
A17: 010I58 | B17: PEO 1 | C17: Develop in depth understanding of the key technologies in data engineering, data science and business analytics.
... A62: 010I69 | B62: PEO 5 | C62: Be self-motivated and remain continuously employable by engaging in lifelong learning.

Sheet POs
A1: PO Master | E1: POs for Mappting | I1: Selected PO
A2: Program | B2: PO | C2: Description | E2: PO Details | I2: PO | J2: Description
A3: 010I38 | B3: PO 1 | C3: An ability to independently carry out research /investigation and development work to solve practical problems. | E3: Pos | F3: Available | G3: Filter | I3: {=_xlfn._xlws.FILTER($B$3:$C$100,$A$3:$A$100=Setup!$B$7,"")} -> PO 1 | J3: An ability to independently carry out research /investigation and development work to solve practical problems.
A4: 010I38 | B4: PO 2 | C4: An ability to write and present a substantial technical report/document. | E4: PO1 | F4: {=TRANSPOSE(_xlfn._xlws.FILTER(Course!$E$2:$I$600,(Course!$A$2:$A$600=Setup!B7)*(Course!$C$2:$C$600=Setup!B8)*(Course!$B$2:$B$600=Setup!#REF!)*(Course!#REF!=Setup!B3),""))} -> #REF! | G4: {=_xlfn._xlws.FILTER($E$4:$E$8,$F$4:$F$8="*","")} -> #REF! | I4: PO 2 | J4: An ability to write and present a substantial technical report/document.
A5: 010I38 | B5: PO 3 | C5: An ability to demonstrate a degree of mastery over the area as per the specialization of the program. The mastery should be at a level higher than the requirements in the appropriate bachelor's program. | E5: PO2 | I5: PO 3 | J5: An ability to demonstrate a degree of mastery over the area as per the specialization of the program. The mastery should be at a level higher than the requirements in the appropriate bachelor program.
A6: 010I38 | B6: PO 4 | C6: An ability to demonstrate knowledge of underlying principles and evaluation methods for integrated circuit technology. | E6: PO3 | I6: PO 4 | J6: An ability to develop software based on theoretical principles and practical knowledge.
A7: 010I38 | B7: PO 5 | C7: An ability to use modern tools for engineering design problems, analyze the performance and optimize the systems-level approaches. | E7: PO4 | I7: PO 5 | J7: An ability to demonstrate knowledge of the underlying principles and evaluation methods for analysing and decision-making.
A8: 010I39 | B8: PO 1 | C8: An ability to independently carry out research /investigation and development work to solve practical problems. | E8: PO5
A9: 010I39 | B9: PO 2 | C9: An ability to write and present a substantial technical report/document.
A10: 010I39 | B10: PO 3 | C10: An ability to demonstrate a degree of mastery over the area as per the specialization of the program. The mastery should be at a level higher than the requirements in the appropriate bachelor program.
A11: 010I39 | B11: PO 4 | C11: An ability to develop and implement embedded systems requirements based on theoretical principles and practical knowledge.
A12: 010I39 | B12: PO 5 | C12: An ability to demonstrate knowledge of the underlying principles and evaluation methods for analyzing and decision-making.
A13: 010I47 | B13: PO 1 | C13: An ability to independently carry out research /investigation and development work to solve practical problems.
A14: 010I47 | B14: PO 2 | C14: An ability to write and present a substantial technical report/document.
A15: 010I47 | B15: PO 3 | C15: An ability to demonstrate a degree of mastery over the area as per the specialization of the program. The mastery should be at a level higher than the requirements in the appropriate bachelor program.
A16: 010I47 | B16: PO 4 | C16: An ability to design, develop scalable, highly available and fault-tolerant cloud solutions, services for business needs and implement well architected cloud architectures based on theoretical principles, ethical considerations, and detailed knowledge of the underlying infrastructure, applications and data.
A17: 010I47 | B17: PO 5 | C17: An ability to demonstrate knowledge of securing cloud resources, data and infrastructure and apply DevOps best practices to automate software development life cycle.
A18: 010I57 | B18: PO 1 | C18: An ability to independently carry out research/investigation and development work to solve practical problems.
A19: 010I57 | B19: PO 2 | C19: An ability to write and present a substantial technical report/document.
A20: 010I57 | B20: PO 3 | C20: Demonstrate a degree of mastery over the area as per the specialization of the program which should be at a level higher than the requirements in an appropriate bachelor program.
... A82: 010I69 | B82: PO 5 | C82: Develop knowledge in Cybersecurity to monitor, prevent, predict and detect and countermeasure cyberattacks using tools and techniques using appropriate security tools.

Sheet COs
A1: Program | B1: Semester | C1: Subject Code | D1: Subject Name | E1: COs | F1: Course Outcome | G1: No. of Hours
A2: 010I61 | B2: I | C2: AME 5002 | D2: Applied Machine Learning | E2: CO1 | F2: Apply different types of supervised machine learning algorithms to practical problems. | G2: 12
A3: 010I61 | B3: I | C3: AME 5002 | D3: Applied Machine Learning | E3: CO2 | F3: Apply different types of unsupervised machine learning algorithms to practical problems. | G3: 12
A4: 010I61 | B4: I | C4: AME 5002 | D4: Applied Machine Learning | E4: CO3 | F4: Analyse different types of machine learning paradigms. | G4: 12
A5: 010I61 | B5: I | C5: AME 5101 | D5: Applied Linear Algebra | E5: CO1 | F5: Apply vector operations for similarity learning. | G5: 10
A6: 010I61 | B6: I | C6: AME 5101 | D6: Applied Linear Algebra | E6: CO2 | F6: Analyse matrix representations in AI & ML models. | G6: 14
A7: 010I61 | B7: I | C7: AME 5101 | D7: Applied Linear Algebra | E7: CO3 | F7: Apply matrix calculus for optimization in learning systems. | G7: 12
A8: 010I61 | B8: I | C8: CCE 5101 | D8: Cloud Application with JAVA and Database with Java | E8: CO1 | F8: Apply Java programming techniques and data interface concepts for application development. | G8: 16
A9: 010I61 | B9: I | C9: CCE 5101 | D9: Cloud Application with JAVA and Database with Java | E9: CO2 | F9: Analyse the techniques to be used for high availability and fault tolerant cloud applications. | G9: 14
A10: 010I61 | B10: I | C10: CCE 5101 | D10: Cloud Application with JAVA and Database with Java | E10: CO3 | F10: Understand the Cloud application architecture and design principles. | G10: 6
A11: 010I61 | B11: I | C11: ESE 5102 | D11: Data Structures and Algorithms | E11: CO1 | F11: Analyse the implementations of elementary data structures. | G11: 12
A12: 010I61 | B12: I | C12: ESE 5102 | D12: Data Structures and Algorithms | E12: CO2 | F12: Design and implementation of data structures like trees and graphs. | G12: 15
A13: 010I61 | B13: I | C13: ESE 5102 | D13: Data Structures and Algorithms | E13: CO3 | F13: Analyse the concepts of divide and conquer, dynamic programming, greedy, and back tracking techniques to efficiently solve problems. | G13: 9
... A504: 010I65 | B504: I | C504: ESE 5105 | D504: Embedded Systems | E504: CO3 | F504: Design multi-tasking applications using real-time operating systems. | G504: 12
A505: 010I65 | B505: I | C505: ESE 5108 | D505: French Language-1* | E505: CO1
A506: 010I65 | B506: I | C506: ESE 5108 | D506: French Language-1* | E506: CO2
A507: 010I65 | B507: I | C507: ESE 5108 | D507: French Language-1* | E507: CO3
A508: 010I65 | B508: I | C508: ESE 5156 | D508: Sensors and Transducers Lab | E508: CO1 | F508: Apply the knowledge of resistive sensors, strain gauge, inductive, and capacitive sensors to develop applications. | G508: 12
A509: 010I65 | B509: I | C509: ESE 5156 | D509: Sensors and Transducers Lab | E509: CO2 | F509: Apply the principles behind ultrasonic and thermal sensors to develop applications. | G509: 12
A510: 010I65 | B510: I | C510: ESE 5156 | D510: Sensors and Transducers Lab | E510: CO3 | F510: Design automation through sensor feedback. | G510: 12
A511: 010I65 | B511: I | C511: ESE 5157 | D511: Vehicular Adhoc Networks Lab | E511: CO1 | F511: Understand the simulation tools for VANET. | G511: 15
A512: 010I65 | B512: I | C512: ESE 5157 | D512: Vehicular Adhoc Networks Lab | E512: CO2 | F512: Apply VANET simulation for routing and traffic applications. | G512: 12
A513: 010I65 | B513: I | C513: ESE 5157 | D513: Vehicular Adhoc Networks Lab | E513: CO3 | F513: Apply emerging technologies to solve real-world challenges in VANETs. | G513: 9
A514: 010I65 | B514: I | C514: ESE 5153 | D514: Microcontrollers and its Applications Lab | E514: CO1 | F514: Apply the knowledge of Microcontrollers to build embedded systems. | G514: 15
A515: 010I65 | B515: I | C515: ESE 5153 | D515: Microcontrollers and its Applications Lab | E515: CO2 | F515: Apply the concepts of timers, and counters for interfacing. | G515: 9
A516: 010I65 | B516: I | C516: ESE 5153 | D516: Microcontrollers and its Applications Lab | E516: CO3 | F516: Analyse the features of SPI, I2C, and interface components to microcontrollers. | G516: 12
A517: 010I65 | B517: I | C517: ESE 5154 | D517: Real Time Operating Systems Lab | E517: CO1 | F517: Implement C programs to efficiently solve problems using multiple processes. | G517: 15
A518: 010I65 | B518: I | C518: ESE 5154 | D518: Real Time Operating Systems Lab | E518: CO2 | F518: Execute C programs for process scheduling and deadlock avoidance algorithms. | G518: 6
A519: 010I65 | B519: I | C519: ESE 5154 | D519: Real Time Operating Systems Lab | E519: CO3 | F519: Design multithreaded programs to solve problems considering process scheduling, deadlocks, or process synchronization on a given scenario. | G519: 15
... A976: 010I69 | B976: II | C976: PSD 5200 | D976: Professional Skill Development - II | E976: CO3 | F976: Use mathematical, reasoning, and domain specific skills to solve objective questionnaires in time. | G976: 4

Sheet References
A1: Program | B1: Semester | C1: Subject Code | D1: Subject Name | E1: References
A2: 010I61 | B2: I | C2: AME 5002 | D2: Applied Machine Learning | E2: 1. G. James, D. Witten, T. Hastie, R. Tibshirani, and J. Taylor, An Introduction to Statistical Learning: with Applications in Python, Springer Texts in Statistics. Cham, Switzerland: Springer, 2023. Online resource available at https://www.statlearning.com/ 2. L. G. Serrano, Grokking Machine Learning, S. Thrun, Foreword, Manning Publications, 2021. Online resource from Manning Publications available at https://www.manning.com/books/grokking-machine-learning 3. J. VanderPlas, Python Data Science Handbook, Sebastopol, CA: O’Reilly Media, 2016. 4. A Course in Machine Learning, Hal Daumé III – Online resource available at http://ciml.info/ 5. Module: Introduction to Machine Learning (https://www.intel.com/content/www/us/en/developer/tools/oneapi/training/academic-program/educators/intro-machine-learning-training-kit.html). 6. Learning path: Understand data science for machine learning (https://learn.microsoft.com/en-us/training/paths/understand-machine-learning/).
A3: 010I61 | B3: I | C3: AME 5101 | D3: Applied Linear Algebra | E3: 1. Introduction to Applied Linear Algebra, Vectors, Matrices, and Least Squares, Stephen Boyd & Lieven Vandenberghe, Cambridge University Press, 1st Edition, 2018. Available online at http://vmls-book.stanford.edu/vmls.pdf. 2. Linear Algebra and Learning from Data, Gilbert Strang, Cambridge Uni. Press, 1st Edition, 2019. 3. IBM AI Engineering Professional Certificate (https://www.coursera.org/professional- certificates/ai-engineer). 4. Deep Learning with Python, François Chollet, Manning Publications, 2nd Edition, 2021. 5. Neural Networks and Deep Learning, Michael A. Nielsen, Determination Press, 2015. Available online at http://neuralnetworksanddeeplearning.com/ 6. Matrix Methods: Applied Linear Algebra, Richard Bronson and Gabriel B. Costa, Academic Press, 3rd Edition, 2008. 7. Introduction to computational thinking (https://computationalthinking.mit.edu/Fall24/).
A4: 010I61 | B4: I | C4: CCE 5101 | D4: Cloud Application with JAVA and Database with Java | E4: 1. Archdeep Bahaga, Vijay Madisetti, “Cloud Computing-A hands on Approach”, Universities Press, 2014. 2. Patrick Naughton and Herbert Schildt, "JAVA 2 – The Complete Reference7th & 8th Edition, Tata McGraw Hill, 2012. 3. Paul Deitel, Harvey Deitel , “How to program with JAVA”, 9th Edition , Deitel Publications, 2012. 4. Abraham Silberschatz, Henry F. Korth and S. Sudharshan, Database System Concepts, Sixth Edition, Tata Mc Graw Hill, 2011. 5. C.J.Date, A.Kannan and S.Swamynathan, An Introduction to Database Systems, Eighth, Edition, Pearson Education, 2006. 6. Atul Kahate, Introduction to Database Management Systems, Pearson Education, New Delhi, 2006. 7. Alexis Leon and Mathews Leon, Database Management Systems, Vikas Publishing House Private Limited, New Delhi, 2003. 8. Raghu Ramakrishnan, Database Management Systems, Fourth Edition, Tata Mc Graw Hill, 2010. 9. Articles, White papers and Transaction Papers. 9. https://www.coursera.org/learn/database-design-postgresql
A5: 010I61 | B5: I | C5: ESE 5102 | D5: Data Structures and Algorithms | E5: 1. “Introduction to Algorithms” Thomas H. Cormen, Charles E. Leiserson, Ronald L. Rivest. 2. “Data Structures& Algorithms” Aho, Hopcroft and Ulmann. 3. “Data structures and algorithm analysis in C” Mark Allen Weiss. 4. “Computer Algorithms” : Ellis Horowitz, Sartaj Sahni, Sanguthevar Rajasekaran. 5. MOOC: https://in.coursera.org/learn/algorithms-on-graphs?specialization=data-structures- 6. algorithms#enroll
A6: 010I61 | B6: I | C6: ESE 5104 | D6: Real Time Operating Systems | E6: 1. “Operating System principles”, Seventh Edition, Abraham Silberschatz, Peter Galvvin, Grag Gagne. John Wiley Publications. 2. “Real – Time Systems and Programming Languages”, Allan Burns, Andy Wellings. 3. “Operating Stems Concepts and Design”, Milan Milenkovic. 4. “Design of Unix Operating System”, Maurice Bach (IPC) 5. “The C Programming Language”, Kerninghan & Ritchie. 6. MOOC:https://in.coursera.org/learn/real-time-embedded-systems-concepts-practices#syllabus.
A7: 010I61 | B7: I | C7: AME 5052 | D7: Applied Machine Learning Lab | E7: 1. G. James, D. Witten, T. Hastie, R. Tibshirani, and J. Taylor, An Introduction to Statistical Learning: with Applications in Python, Springer Texts in Statistics. Cham, Switzerland: Springer, 2023. Online resource available at https://www.statlearning.com/ 2. L. G. Serrano, Grokking Machine Learning, S. Thrun, Foreword, Manning Publications, 2021. Online resource from Manning Publications available at https://www.manning.com/books/grokking-machine-learning 3. J. VanderPlas, Python Data Science Handbook, Sebastopol, CA: O’Reilly Media, 2016. 4. A Course in Machine Learning, Hal Daumé III – Online resource available at http://ciml.info/ 5. Module: Introduction to Machine Learning (https://www.intel.com/content/www/us/en/developer/tools/oneapi/training/academic-program/educators/intro-machine-learning-training-kit.html). 6. Learning path: Understand data science for machine learning (https://learn.microsoft.com/en-us/training/paths/understand-machine-learning/).
A8: 010I61 | B8: I | C8: AME 5151 | D8: Applied Linear Algebra Lab | E8: 1. S. Boyd and L. Vandenberghe, *Introduction to Applied Linear Algebra: Vectors, Matrices, and Least Squares*, 1st ed. Cambridge, U.K.: Cambridge University Press, 2018. [Online]. Available: http://vmls-book.stanford.edu/vmls.pdf 2. G. Strang, *Linear Algebra and Learning from Data*, 1st ed. Cambridge, U.K.: Cambridge University Press, 2019. 3. IBM, “AI Engineering Professional Certificate,” Coursera. [Online]. Available: https://www.coursera.org/professional-certificates/ai-engineer 4. F. Chollet, *Deep Learning with Python*, 2nd ed. Shelter Island, NY, USA: Manning Publications, 2021. 5. M. A. Nielsen, *Neural Networks and Deep Learning*. Determination Press, 2015. [Online]. Available: http://neuralnetworksanddeeplearning.com/ 6. R. Bronson and G. B. Costa, *Matrix Methods: Applied Linear Algebra*, 3rd ed. Burlington, MA, USA: Academic Press, 2008. 7. Massachusetts Institute of Technology, “Introduction to Computational Thinking,” 2024. [Online]. Available: https://computationalthinking.mit.edu/Fall24/
A9: 010I61 | B9: I | C9: CCE 5151 | D9: Cloud Application with JAVA and Database with Java Lab | E9: 1. Archdeep Bahaga, Vijay Madisetti, “Cloud Computing-A hands on Approach”, Universities Press, 2014. 2. Archdeep Bahaga, Vijay Madisetti, “Internet of Things - A hands on Approach”, Universities Press, 2015. 3. Patrick Naughton and Herbert Schildt, "JAVA 2 – The Complete Reference7th & 8th Edition, Tata McGraw Hill, 2012. 4. Paul Deitel, Harvey Deitel, “How to program with JAVA”, 9th Edition, Deitel Publications, 2012. 5. Danny Coward, “Java WebSocket Programming”, McGraw-Hill Education, 2014. 6. Jobinesh Purushothaman,” RESTful Java Web Services”, Second Edition, Packt Publishing, 2015.
A10: 010I61 | B10: I | C10: ESE 5152 | D10: Data Structures and Algorithms Lab | E10: 1. Introduction to Algorithms – Thomas H. Cormen, Charles E. Leiserson, Ronald L. Rivest. MIT Press. 2. Data Structures and Algorithms – Aho, Hopcroft and Ulmann. Pearson Publishers.
A11: 010I61 | B11: I | C11: ESE 5154 | D11: Real Time Operating Systems Lab | E11: 1. “Operating System principles”, Seventh Edition, Abraham Silberschatz, Peter Galvvin, Grag Gagne. John Wiley Publications. 2. “Real – Time Systems and Programming Languages”, Allan Burns, Andy Wellings. 3. “Operating Stems Concepts and Design”, Milan Milenkovic. 4. “Design of Unix Operating System”, Maurice Bach (IPC). 5. “The C Programming Language”, Kerninghan & Ritchie.
A12: 010I61 | B12: I | C12: MPT 5100 | D12: Mini Project - I | E12: 1. Research Methodology, Methods and Techniques, C. R. Kothari; New Age International Publishers; 2nd Revised Edition,2004 2. (https://www.jsscacs.edu.in/sites/default/files/Files/Statistics%20and%20Research%20by%20Kothari.pdf). 3. Project Management by Adrienne Watt - BCcampus Open Textbook project 4. (https://www.opentextbooks.org.hk/system/files/export/15/15694/pdf/Project_Management_15694.pdf). 5. Research articles and Online Resources.
... A325: 010I69 | B325: II | C325: PSD 5200 | D325: Professional Skill Development - II | E325: 1. R S Aggarwal. Quantitative Aptitude for Competitive Examinations. S Chand, 2017. 2. McDowell, Gayle Laakmann. Cracking the coding interview: 189 programming questions and solutions. CareerCup, LLC, 2015. 3. Domain specific tools and online resources.

Sheet Course 24 & 25
A1: Batch | B1: Academic Year | C1: Program Code | D1: Semester | E1: Course Code | F1: Course Name | G1: PO1 | H1: PO2 | I1: PO3 | J1: PO4 | K1: PO5 | L1: Sort No | M1: Short Code | N1: Subject Class | O1: Status | Q1: Subject Code | R1: Subject Name
A2: 2024 | B2: 2024-2025 | C2: 010I38 | D2: I | E2: VLS 5001 | F2: High Level Digital Design | I2: * | J2: * | L2: 1 | M2: HLDD | N2: Theory | O2: Active | Q2: {=_xlfn._xlws.FILTER($E$2:$F$600,(N2:N600="Theory")*(O2:O600="Active")*('Course 24 & 25'!$C$2:$C$600=Setup!$B$7)*('Course 24 & 25'!$D$2:$D$600=Setup!#REF!),"")} -> #REF!
A3: 2024 | B3: 2024-2025 | C3: 010I38 | D3: I | E3: VLS 5101 | F3: Data Structures | G3: * | I3: * | J3: * | L3: 2 | M3: DS | N3: Theory | O3: Active
A4: 2024 | B4: 2024-2025 | C4: 010I38 | D4: I | E4: VLS 5102 | F4: Digital Systems and VLSI Design | I4: * | J4: * | K4: * | L4: 3 | M4: DSVD | N4: Theory | O4: Active
A5: 2024 | B5: 2024-2025 | C5: 010I38 | D5: I | E5: VLS 5103 | F5: Verification | I5: * | J5: * | L5: 4 | M5: VER | N5: Theory | O5: Active
A6: 2024 | B6: 2024-2025 | C6: 010I38 | D6: I | E6: VLS 5131 | F6: CAD for VLSI | G6: * | I6: * | K6: * | L6: 5 | M6: CAD | N6: Theory | O6: Active
A7: 2024 | B7: 2024-2025 | C7: 010I38 | D7: I | E7: VLS 5132 | F7: System on chip Design | I7: * | J7: * | L7: 6 | M7: SoC | N7: Theory | O7: Active
A8: 2024 | B8: 2024-2025 | C8: 010I38 | D8: I | E8: ESD 5001 | F8: Digital Signal Processing | G8: * | I8: * | J8: * | L8: 7 | N8: Theory
A9: 2024 | B9: 2024-2025 | C9: 010I38 | D9: I | E9: MVT 5101 | F9: VLSI Fabrication Technology | I9: * | J9: * | L9: 8 | N9: Theory
A10: 2024 | B10: 2024-2025 | C10: 010I38 | D10: I | E10: VLS 5051 | F10: High Level Digital Design Lab | I10: * | J10: * | K10: * | L10: 9 | M10: HLDD Lab | N10: Lab | O10: Active
A11: 2024 | B11: 2024-2025 | C11: 010I38 | D11: I | E11: VLS 5151 | F11: Data Structures Lab | G11: * | I11: * | J11: * | L11: 10 | M11: DS Lab | N11: Lab | O11: Active
A12: 2024 | B12: 2024-2025 | C12: 010I38 | D12: I | E12: VLS 5152 | F12: Digital Systems and VLSI Design Lab | I12: * | J12: * | K12: * | L12: 11 | M12: DSVD Lab | N12: Lab | O12: Active
A13: 2024 | B13: 2024-2025 | C13: 010I38 | D13: I | E13: VLS 5153 | F13: Verification Lab | I13: * | J13: * | L13: 12 | M13: VER Lab | N13: Lab | O13: Active
A14: 2024 | B14: 2024-2025 | C14: 010I38 | D14: I | E14: VLS 5181 | F14: CAD for VLSI Lab | G14: * | I14: * | K14: * | L14: 13 | M14: CAD Lab | N14: Lab | O14: Active
A15: 2024 | B15: 2024-2025 | C15: 010I38 | D15: I | E15: VLS 5182 | F15: System on chip Design Lab | J15: * | K15: * | L15: 14 | M15: SoC Lab | N15: Lab | O15: Active
A16: 2024 | B16: 2024-2025 | C16: 010I38 | D16: I | E16: ESD 5051 | F16: Digital Signal Processing Lab | G16: * | I16: * | J16: * | L16: 15 | N16: Lab
A17: 2024 | B17: 2024-2025 | C17: 010I38 | D17: I | E17: MVT 5151 | F17: VLSI Fabrication Technology Lab | I17: * | J17: * | L17: 16 | N17: Lab
A18: 2024 | B18: 2024-2025 | C18: 010I38 | D18: I | E18: MPT 5100 | F18: Mini Project - I | G18: * | H18: * | I18: * | J18: * | K18: * | L18: 17 | M18: MP 1 | N18: Project | O18: Active
A19: 2024 | B19: 2024-2025 | C19: 010I38 | D19: I | E19: PSD 5100 | F19: Professional Skill Development - I | G19: * | H19: * | L19: 18 | M19: PSD 1 | N19: Seminar | O19: Active
A20: 2024 | B20: 2024-2025 | C20: 010I38 | D20: II | E20: VLS 5201 | F20: Advanced VLSI Design | G20: * | I20: * | J20: * | K20: * | L20: 19 | M20: AVD | N20: Theory | O20: Active
A21: 2024 | B21: 2024-2025 | C21: 010I38 | D21: II | E21: VLS 5202 | F21: Low Power VLSI Design | G21: * | I21: * | J21: * | K21: * | L21: 20 | M21: LPVD | N21: Theory | O21: Active
A22: 2024 | B22: 2024-2025 | C22: 010I38 | D22: II | E22: VLS 5203 | F22: Scripting for VLSI | G22: * | I22: * | J22: * | L22: 21 | M22: SCR | N22: Theory | O22: Active
A23: 2024 | B23: 2024-2025 | C23: 010I38 | D23: II | E23: VLS 5204 | F23: Universal Verification Methodology | I23: * | J23: * | L23: 22 | M23: UVM | N23: Theory | O23: Active
A24: 2024 | B24: 2024-2025 | C24: 010I38 | D24: II | E24: VLS 5231 | F24: Advanced Logic Synthesis | I24: * | J24: * | L24: 23 | N24: Theory
A25: 2024 | B25: 2024-2025 | C25: 010I38 | D25: II | E25: VLS 5233 | F25: Machine learning for VLSI Design | I25: * | J25: * | L25: 24 | N25: Theory
A26: 2024 | B26: 2024-2025 | C26: 010I38 | D26: II | E26: VLS 5234 | F26: Physical Design | I26: * | J26: * | L26: 25 | M26: PD | N26: Theory | O26: Active
A27: 2024 | B27: 2024-2025 | C27: 010I38 | D27: II | E27: ENP 5230 | F27: Entrepreneurship | I27: * | J27: * | L27: 26 | N27: Theory
A28: 2024 | B28: 2024-2025 | C28: 010I38 | D28: II | E28: ESD 5232 | F28: IT Project Management | G28: * | I28: * | K28: * | L28: 27 | N28: Theory
A29: 2024 | B29: 2024-2025 | C29: 010I38 | D29: II | E29: VLS 5251 | F29: Advanced VLSI Design Lab | G29: * | I29: * | J29: * | K29: * | L29: 28 | M29: AVD Lab | N29: Lab | O29: Active
A30: 2024 | B30: 2024-2025 | C30: 010I38 | D30: II | E30: VLS 5252 | F30: Low Power VLSI Design Lab | G30: * | I30: * | J30: * | K30: * | L30: 29 | M30: LPVD Lab | N30: Lab | O30: Active
A31: 2024 | B31: 2024-2025 | C31: 010I38 | D31: II | E31: VLS 5253 | F31: Scripting for VLSI Lab | G31: * | I31: * | J31: * | L31: 30 | M31: SCR Lab | N31: Lab | O31: Active
A32: 2024 | B32: 2024-2025 | C32: 010I38 | D32: II | E32: VLS 5254 | F32: Universal Verification Methodology Lab | J32: * | K32: * | L32: 31 | M32: UVM Lab | N32: Lab | O32: Active
A33: 2024 | B33: 2024-2025 | C33: 010I38 | D33: II | E33: VLS 5281 | F33: Advanced Logic Synthesis Lab | I33: * | J33: * | L33: 32 | N33: Lab
A34: 2024 | B34: 2024-2025 | C34: 010I38 | D34: II | E34: VLS 5283 | F34: Machine Learning for VLSI Design Lab | I34: * | J34: * | L34: 33 | N34: Lab
A35: 2024 | B35: 2024-2025 | C35: 010I38 | D35: II | E35: VLS 5284 | F35: Physical Design Lab | J35: * | K35: * | L35: 34 | M35: PD Lab | N35: Lab | O35: Active
A36: 2024 | B36: 2024-2025 | C36: 010I38 | D36: II | E36: ENP 5280 | F36: Entrepreneurship Lab | I36: * | J36: * | L36: 35 | N36: Lab
A37: 2024 | B37: 2024-2025 | C37: 010I38 | D37: II | E37: ESD 5282 | F37: IT Project Management Lab | G37: * | I37: * | K37: * | L37: 36 | N37: Lab
A38: 2024 | B38: 2024-2025 | C38: 010I38 | D38: II | E38: MPT 5200 | F38: Mini Project - II | G38: * | H38: * | I38: * | J38: * | K38: * | L38: 37 | M38: MP 2 | N38: Project | O38: Active
A39: 2024 | B39: 2024-2025 | C39: 010I38 | D39: II | E39: PSD 5200 | F39: Professional Skill Development - II | I39: * | J39: * | K39: * | L39: 38 | M39: PSD 2 | N39: Seminar | O39: Active
A40: 2024 | B40: 2024-2025 | C40: 010I38 | D40: III & IV | E40: VLS 6098 | F40: Project Work | G40: * | H40: * | I40: * | J40: * | K40: * | L40: 39 | N40: Project
...

Sheet Faculty
A1: Faculty Master
A2: Faculty Short Code | B2: Faculty Code | C2: Faculty Name | D2: Signature
A3: BDR | B3: MAHE0004209 | C3: Dr. B Dinesh Rao | D3: #VALUE!
A4: PKS | B4: MAHE0004212 | C4: Dr. Prashanth Kumar Shetty | D4: #VALUE!
A5: SN | B5: MAHE0004783 | C5: Mr. Shridhar Nayak | D5: #VALUE!
A6: KP | B6: MAHE0004785 | C6: Dr. Keerthana Prasad | D6: #VALUE!
A7: DPK | B7: MAHE0004835 | C7: Dr. Deepak Rao | D7: #VALUE!
A8: SNM | B8: MAHE0004926 | C8: Dr. Sathyendranath Malli | D8: #VALUE!
A9: KB | B9: MAHE0007015 | C9: Ms. Keerthana B | D9: #VALUE!
A10: ARAJ | B10: MAHE0007066 | C10: Dr. Arockiaraj | D10: #VALUE!
A11: RK | B11: MAHE0007069 | C11: Ms. Ravikala Kamath | D11: #VALUE!
A12: RP | B12: MAHE0007611 | C12: Dr. Raghavendra Prabhu | D12: #VALUE!
A13: BB | B13: MAHE0008359 | C13: Mr. Balaji B | D13: #VALUE!
A14: MS | B14: MAHE0008403 | C14: Dr. Madhushankar Bhat | D14: #VALUE!
... A22: DP | B22: MAHE0026851 | C22: Dr. Devi Prasad M | D22: #VALUE!
A23: WB | B23: MAHE0028188 | C23: Mr. Winson Benedict Fernandes
A24: NM | B24: MAHE0028191 | C24: Ms. Nimisha | D24: #VALUE!
A25: RS | B25: MAHE0028454 | C25: Dr. Richa Sharma | D25: #VALUE!
A29: VSNS | B29: VF_010_04 | C29: Suchitra N Shenoy | D29: #VALUE!
A30: VJR | B30: GUEST004 | C30: Jyothsna Rai | D30: #VALUE!

Sheet TImetable
A1: Rooms | B1: Day | C1: Time | E1: Program Code | F1: Day | G1: Time | H1: Course SC | I1: Course Code | K1: Program | L1: Room
A2: LG01-LH02 | B2: Monday | C2: 8-9 | I2: {=IF(E2="","",_xlfn.XLOOKUP(E2&H2,Course!$A$2:$A$582&Course!$K$2:$K$582,Course!$C$2:$C$582,""))} | K2: 010I61 | L2: LG01-LH08
A3: LG01-LH08 | B3: Tuesday | C3: 9-10 | I3: {=IF(E3="","",_xlfn.XLOOKUP(E3&H3,Course!$A$2:$A$582&Course!$K$2:$K$582,Course!$C$2:$C$582,""))} | K3: 010I62 | L3: LG01-LH10
A4: LG01-LH10 | B4: Wednesday | C4: 10-11 | I4: {=IF(E4="","",_xlfn.XLOOKUP(E4&H4,Course!$A$2:$A$582&Course!$K$2:$K$582,Course!$C$2:$C$582,""))} | K4: 010I63 | L4: LG01-LH11
A5: LG01-LH11 | B5: Thursday | C5: 11-12 | I5: {=IF(E5="","",_xlfn.XLOOKUP(E5&H5,Course!$A$2:$A$582&Course!$K$2:$K$582,Course!$C$2:$C$582,""))} | K5: 010I64 | L5: LG01-LH11
A6: LG01-LH12 | B6: Friday | C6: 12-1 | I6: {=IF(E6="","",_xlfn.XLOOKUP(E6&H6,Course!$A$2:$A$582&Course!$K$2:$K$582,Course!$C$2:$C$582,""))} | K6: 010I65 | L6: LG01-LH09
A7: LG02-LH04 | B7: Saturday | C7: 1-2 | I7: {=IF(E7="","",_xlfn.XLOOKUP(E7&H7,Course!$A$2:$A$582&Course!$K$2:$K$582,Course!$C$2:$C$582,""))} | K7: 010I66 | L7: LG01-LH12
A8: LG01-LH09 | C8: 2-3 | I8: {=IF(E8="","",_xlfn.XLOOKUP(E8&H8,Course!$A$2:$A$582&Course!$K$2:$K$582,Course!$C$2:$C$582,""))} | K8: 010I67 | L8: LG01-LH08
A9: LG01-LH01 | C9: 3-4 | I9: {=IF(E9="","",_xlfn.XLOOKUP(E9&H9,Course!$A$2:$A$582&Course!$K$2:$K$582,Course!$C$2:$C$582,""))} | K9: 010I68 | L9: LG01-LH02
C10: 4-5 | I10: {=IF(E10="","",_xlfn.XLOOKUP(E10&H10,Course!$A$2:$A$582&Course!$K$2:$K$582,Course!$C$2:$C$582,""))} | K10: 010I69 | L10: LG01-LH01
I11: {=IF(E11="","",_xlfn.XLOOKUP(E11&H11,Course!$A$2:$A$582&Course!$K$2:$K$582,Course!$C$2:$C$582,""))}
I12: {=IF(E12="","",_xlfn.XLOOKUP(E12&H12,Course!$A$2:$A$582&Course!$K$2:$K$582,Course!$C$2:$C$582,""))}
I13: {=IF(E13="","",_xlfn.XLOOKUP(E13&H13,Course!$A$2:$A$582&Course!$K$2:$K$582,Course!$C$2:$C$582,""))}
I14: {=IF(E14="","",_xlfn.XLOOKUP(E14&H14,Course!$A$2:$A$582&Course!$K$2:$K$582,Course!$C$2:$C$582,""))}
I15: {=IF(E15="","",_xlfn.XLOOKUP(E15&H15,Course!$A$2:$A$582&Course!$K$2:$K$582,Course!$C$2:$C$582,""))}
I16: {=IF(E16="","",_xlfn.XLOOKUP(E16&H16,Course!$A$2:$A$582&Course!$K$2:$K$582,Course!$C$2:$C$582,""))}
I17: {=IF(E17="","",_xlfn.XLOOKUP(E17&H17,Course!$A$2:$A$582&Course!$K$2:$K$582,Course!$C$2:$C$582,""))}
I18: {=IF(E18="","",_xlfn.XLOOKUP(E18&H18,Course!$A$2:$A$582&Course!$K$2:$K$582,Course!$C$2:$C$582,""))}
I19: {=IF(E19="","",_xlfn.XLOOKUP(E19&H19,Course!$A$2:$A$582&Course!$K$2:$K$582,Course!$C$2:$C$582,""))}
I20: {=IF(E20="","",_xlfn.XLOOKUP(E20&H20,Course!$A$2:$A$582&Course!$K$2:$K$582,Course!$C$2:$C$582,""))}
I21: {=IF(E21="","",_xlfn.XLOOKUP(E21&H21,Course!$A$2:$A$582&Course!$K$2:$K$582,Course!$C$2:$C$582,""))}
I22: {=IF(E22="","",_xlfn.XLOOKUP(E22&H22,Course!$A$2:$A$582&Course!$K$2:$K$582,Course!$C$2:$C$582,""))}
... I500: {=IF(E500="","",_xlfn.XLOOKUP(E500&H500,Course!$A$2:$A$582&Course!$K$2:$K$582,Course!$C$2:$C$582,""))}

Sheet COs 24 & 25
A1: Academic Year | B1: Subject Type | C1: Subject Class | D1: Semester | E1: Program | F1: Subject Code | G1: Subject Name | H1: COs | I1: Course Outcome | J1: No. of Hours
A2: 2024-2025 | B2: Theory | C2: Core | D2: I | E2: 010I38 | F2: VLS 5001 | G2: High Level Digital Design | H2: CO1 | I2: Apply combination logic gates and arithmetic circuits
A3: 2024-2025 | B3: Theory | C3: Core | D3: I | E3: 010I38 | F3: VLS 5001 | G3: High Level Digital Design | H3: CO2 | I3: Analyze data path functional units and optimization
A4: 2024-2025 | B4: Theory | C4: Core | D4: I | E4: 010I38 | F4: VLS 5001 | G4: High Level Digital Design | H4: CO3 | I4: Analyze sequential logic and finite state machine circuits with timing aspect
A5: 2024-2025 | B5: Theory | C5: Core | D5: I | E5: 010I38 | F5: VLS 5001 | G5: High Level Digital Design | H5: CO4 | I5: Apply Field Programming Gate Arrays and First In First Out
A6: 2024-2025 | B6: Theory | C6: Core | D6: I | E6: 010I38 | F6: VLS 5001 | G6: High Level Digital Design | H6: CO5 | I6: Analyze AMBA bus architecture
A7: 2024-2025 | B7: Theory | C7: Core | D7: I | E7: 010I38 | F7: VLS 5101 | G7: Data Structures | H7: CO1 | I7: Design programs for implementation of linked lists, stack and queues.
A8: 2024-2025 | B8: Theory | C8: Core | D8: I | E8: 010I38 | F8: VLS 5101 | G8: Data Structures | H8: CO2 | I8: Design programs for implementation of binary search tree, sorting and searching, dictionary and Hash Table
A9: 2024-2025 | B9: Theory | C9: Core | D9: I | E9: 010I38 | F9: VLS 5101 | G9: Data Structures | H9: CO3 | I9: Design programs for graphs and shortest path techniques.
A10: 2024-2025 | B10: Theory | C10: Core | D10: I | E10: 010I38 | F10: VLS 5102 | G10: Digital Systems and VLSI Design | H10: CO1 | I10: Explain various CMOS process technologies and manufacturing issues.
A11: 2024-2025 | B11: Theory | C11: Core | D11: I | E11: 010I38 | F11: VLS 5102 | G11: Digital Systems and VLSI Design | H11: CO2 | I11: Analyze the static and dynamic behavior of MOSFETs and the secondary effects of the MOS transistor model.
A12: 2024-2025 | B12: Theory | C12: Core | D12: I | E12: 010I38 | F12: VLS 5102 | G12: Digital Systems and VLSI Design | H12: CO3 | I12: Design and test CMOS combinational and sequential logic at transistor level, including mask layout.
A13: 2024-2025 | B13: Theory | C13: Core | D13: I | E13: 010I38 | F13: VLS 5102 | G13: Digital Systems and VLSI Design | H13: CO4 | I13: Describe circuit characterization and manufacturing issues.
... A544: 2024-2025 | B544: Lab | C544: ELE 2 | D544: II | E544: 010I60 | F544: MVT 5281 | G544: IC Packaging Technology Lab | H544: CO3 | I544: Analyze three-dimensional integrated circuits packaging
A545: 2024-2025 | B545: Seminar | C545: Core | D545: I | F545: PSD 5100 | G545: Professional Skill Development - I | H545: CO1 | I545: Identify and synthesize important themes in the field of engineering which transform socio-economic ecosystem.
A546: 2024-2025 | B546: Seminar | C546: Core | D546: I | F546: PSD 5100 | G546: Professional Skill Development - I | H546: CO2 | I546: Develop competence to communicate effectively in oral and written forms.
A547: 2024-2025 | B547: Seminar | C547: Core | D547: I | F547: PSD 5100 | G547: Professional Skill Development - I | H547: CO3 | I547: Effective management of time, involve in reflective learning and adhere to the professional code of conduct.
A548: 2024-2025 | B548: Seminar | C548: Core | D548: II | F548: PSD 5100 | G548: Professional Skill Development - II | H548: CO1 | I548: Develop the skills needed for approaching technical and HR interviews.
A549: 2024-2025 | B549: Seminar | C549: Core | D549: II | F549: PSD 5100 | G549: Professional Skill Development - II | H549: CO2 | I549: Use mathematical, reasoning, and domain specific skills to solve objective questionnaires in time.
A550: 2024-2025 | B550: Seminar | C550: Core | D550: II | F550: PSD 5100 | G550: Professional Skill Development - II | H550: CO3 | I550: Demonstrate depth of knowledge in the chosen field of study.
A551: 2025-2026 | B551: Theory | C551: Core | D551: I | E551: 010I61 | F551: AME 5001 | G551: Applied Generative AI and Machine Learning | H551: CO1 | I551: Apply different types of supervised and unsupervised machine learning algorithms to practical problems. | J551: 12
A552: 2025-2026 | B552: Theory | C552: Core | D552: I | E552: 010I61 | F552: AME 5001 | G552: Applied Generative AI and Machine Learning | H552: CO2 | I552: Analyse different types of machine learning paradigms. | J552: 12
A553: 2025-2026 | B553: Theory | C553: Core | D553: I | E553: 010I61 | F553: AME 5001 | G553: Applied Generative AI and Machine Learning | H553: CO3 | I553: Effectively apply large language models for practical problems. | J553: 12
A554: 2025-2026 | B554: Theory | C554: Core | D554: I | E554: 010I61 | F554: BDE 5002 | G554: Principles of Data Visualization | H554: CO1 | I554: Implement web scraping techniques to extract data from websites. | J554: 9
A555: 2025-2026 | B555: Theory | C555: Core | D555: I | E555: 010I61 | F555: BDE 5002 | G555: Principles of Data Visualization | H555: CO2 | I555: Organize raw data for analysis using data manipulation techniques. | J555: 15
A556: 2025-2026 | B556: Theory | C556: Core | D556: I | E556: 010I61 | F556: BDE 5002 | G556: Principles of Data Visualization | H556: CO3 | I556: Interpret data using data visualization techniques. | J556: 12
A557: 2025-2026 | B557: Theory | C557: Core | D557: I | E557: 010I61 | F557: CCE 5101 | G557: Cloud Application with Java and Database | H557: CO1 | I557: Apply Java programming techniques and data interface concepts for application development. | J557: 16
A558: 2025-2026 | B558: Theory | C558: Core | D558: I | E558: 010I61 | F558: CCE 5101 | G558: Cloud Application with Java and Database | H558: CO2 | I558: Analyze the techniques to be used for high availability and fault tolerant cloud applications. | J558: 14
A559: 2025-2026 | B559: Theory | C559: Core | D559: I | E559: 010I61 | F559: CCE 5101 | G559: Cloud Application with Java and Database | H559: CO3 | I559: Understand the Cloud application architecture and design principles. | J559: 6
A560: 2025-2026 | B560: Theory | C560: Core | D560: I | E560: 010I61 | F560: ESE 5102 | G560: Data Structures and Algorithms | H560: CO1 | I560: Analyze the implementations of elementary data structures. | J560: 12
A561: 2025-2026 | B561: Theory | C561: Core | D561: I | E561: 010I61 | F561: ESE 5102 | G561: Data Structures and Algorithms | H561: CO2 | I561: Design and implementation of data structures like trees and graphs. | J561: 15
A562: 2025-2026 | B562: Theory | C562: Core | D562: I | E562: 010I61 | F562: ESE 5102 | G562: Data Structures and Algorithms | H562: CO3 | I562: Analyze the concepts of divide and conquer, dynamic programming, greedy, and back tracking techniques to efficiently solve problems. | J562: 9
... A601: 2025-2026 | B601: Theory | C601: ELE 1 | D601: II | E601: 010I61 | F601: CCE 5203 | G601: Cloud Security Essentials | H601: CO3 | I601: Examine logging and monitoring services to identify the incidence. | J601: 12
A602: 2025-2026 | B602: Theory | C602: ELE 1 | D602: II | E602: 010I61 | F602: ESE 5234 | G602: Entrepreneurship | H602: CO1 | I602: Explain the importance of entrepreneurship and entrepreneurial development model, social responsibilities of business.
A603: 2025-2026 | B603: Theory | C603: ELE 1 | D603: II | E603: 010I61 | F603: ESE 5234 | G603: Entrepreneurship | H603: CO2 | I603: Describe Entrepreneurial Traits and Factors affecting Entrepreneurship process.
A604: 2025-2026 | B604: Theory | C604: ELE 1 | D604: II | E604: 010I61 | F604: ESE 5234 | G604: Entrepreneurship | H604: CO3 | I604: Discuss Business Start-up Process.
A605: 2025-2026 | B605: Theory | C605: ELE 1 | D605: II | E605: 010I61 | F605: ESE 5234 | G605: Entrepreneurship | H605: CO4 | I605: Summarize a business and marketing plan for entrepreneurs.
A606: 2025-2026 | B606: Theory | C606: ELE 2 | D606: II | E606: 010I61 | F606: AME 5242 | G606: Natural Language Processing Principles and Applications | H606: CO1 | I606: Understand text processing for information extraction and retrieval. | J606: 10
A607: 2025-2026 | B607: Theory | C607: ELE 2 | D607: II | E607: 010I61 | F607: AME 5242 | G607: Natural Language Processing Principles and Applications | H607: CO2 | I607: Compare and contrast state-of-the-art word vectorization models for real-world problems. | J607: 12
A608: 2025-2026 | B608: Theory | C608: ELE 2 | D608: II | E608: 010I61 | F608: AME 5242 | G608: Natural Language Processing Principles and Applications | H608: CO3 | I608: Apply deep learning-based approaches for natural language processing tasks. | J608: 14
...

Sheet Rough Sheet
E5: Solving linear equations. | F5: CO1
E6: Applications in deep learning - Introduction to sensitivity and gradient in one dimension. | F6: CO3
E7: Chain rule. Matrix derivatives. | F7: CO3
E8: Gradient descent. | F8: CO2
E9: Training the artificical neural networks - backward propagation of errors. | F9: CO2
E10: Backpropagation algorithm. | F10: CO3
E11: Introduction to Attention mechanism. | F11: CO1
E12: Impementation details of attention mechanism in large language models. | F12: CO3
E13: Impementation details of attention mechanism in large language models. | F13: CO3
E14: Tensor cores and GPU architectures | F14: CO2
E15: Tensor cores and GPU architectures | F15: CO2

Sheet Setup
A1: Faculty Code (MAHE0xxxx) | B1: MAHE0026851 | C1: =IF(B5="","","COs of "&B5) -> COs of Applied Linear Algebra
A2: Faculty Name | B2: =IF(B1="","",IFERROR(VLOOKUP(B1,Faculty!$B$3:$C$40,2,0),"Invalid Faculty Code")) -> Dr. Devi Prasad M | C2: =IF($B$5="","","COs") -> COs | D2: =IF($B$5="","","Course Outcome") -> Course Outcome | E2: =IF($B$5="","","BL Mapping") -> BL Mapping | F2: =IF($B$5="","","1st PO") -> 1st PO | G2: =IF($B$5="","","2nd PO (If any)") -> 2nd PO (If any) | H2: =IF($B$5="","","3rd PO (If any)") -> 3rd PO (If any)
A3: Academic Year | B3: 2026-2027 | C3: {=IF(B5="","",_xlfn._xlws.FILTER(COs!$E$2:$F$1000,(COs!$A$2:$A$1000=B7)*(COs!$C$2:$C$1000=B8),""))} -> CO1 | D3: Apply vector operations for similarity learning. | E3: 3 | F3: PO3 | I3: =IF(AND(F3<>"",G3="",H3=""),F3,IF(AND(F3<>"",G3<>"",H3=""),F3&","&G3,IF(AND(F3<>"",G3<>"",H3<>""),F3&","&G3&","&H3,""))) -> PO3
A4: Program Name | B4: Master of Engineering – M.E in Computer Science and Engineering | C4: CO2 | D4: Analyse matrix representations in AI & ML models. | E4: 4 | F4: PO4 | G4: PO3 | I4: =IF(AND(F4<>"",G4="",H4=""),F4,IF(AND(F4<>"",G4<>"",H4=""),F4&","&G4,IF(AND(F4<>"",G4<>"",H4<>""),F4&","&G4&","&H4,""))) -> PO4,PO3
A5: Course Name | B5: Applied Linear Algebra | C5: CO3 | D5: Apply matrix calculus for optimization in learning systems. | E5: 3 | F5: PO3 | I5: =IF(AND(F5<>"",G5="",H5=""),F5,IF(AND(F5<>"",G5<>"",H5=""),F5&","&G5,IF(AND(F5<>"",G5<>"",H5<>""),F5&","&G5&","&H5,""))) -> PO3
A6: Semester | B6: Semester - I | I6: =IF(AND(F6<>"",G6="",H6=""),F6,IF(AND(F6<>"",G6<>"",H6=""),F6&","&G6,IF(AND(F6<>"",G6<>"",H6<>""),F6&","&G6&","&H6,"")))
A7: Program Code | B7: =IF(B4="","",_xlfn.XLOOKUP(B4,Program!$C$2:$C$50,Program!$B$2:$B$50,"")) -> 010I61 | I7: =IF(AND(F7<>"",G7="",H7=""),F7,IF(AND(F7<>"",G7<>"",H7=""),F7&","&G7,IF(AND(F7<>"",G7<>"",H7<>""),F7&","&G7&","&H7,"")))
A8: Course Code | B8: {=IF(B5="","",_xlfn.XLOOKUP(B7&B5,Course!$A$2:$A$500&Course!$D$2:$D$500,Course!$C$2:$C$500,""))} -> AME 5101
A9: Course Coordinator | B9: =IF(B2="","",B2) -> Dr. Devi Prasad M | C9: =IFERROR(VLOOKUP(B2,Faculty!$C$3:$D$100,2,0),"") -> #VALUE!
A10: Program Coordinator | B10: =IFERROR(VLOOKUP(IFERROR(VLOOKUP(B7,Program!$B$2:$D$50,3,0),""),Faculty!$A$3:$D$50,3,0),"") -> Dr. Sathyendranath Malli | C10: =IFERROR(VLOOKUP(B10,Faculty!$C$3:$D$100,2,0),"") -> #VALUE!
A11: Subject Type | B11: {=IF(B2="","",_xlfn.XLOOKUP(B7&B8,Course!$A$2:$A$500&Course!$C$2:$C$500,Course!$M$2:$M$500,""))} -> Core
A12: Sem | B12: =IF(B6="Semester - I","I","II") -> I

Sheet Lesson Plan
A1: =IF(Setup!$B$5="","","Lesson Plan of "&Setup!$B$5) -> Lesson Plan of Applied Linear Algebra
A2: =IF($A$1="","","S.No.") -> S.No. | B2: =IF($A$1="","","L.No.") -> L.No. | C2: =IF($A$1="","","TOPICS") -> TOPICS | D2: =IF($A$1="","","Course Outcome Addressed") -> Course Outcome Addressed | F2: =IF($A$1="","","COs") -> COs | G2: =IF($A$1="","","Expected No. of Hours") -> Expected No. of Hours | H2: =IF($A$1="","","Remaining No. of Hours") -> Remaining No. of Hours
A3: =IF($A$1="","",IF(Setup!B2="","",IF(C3="","",IF(C3="MID SEMESTER EXAM","MSE",0)))) -> 0 | B3: =IF($A$1="","",IF(Setup!B2="","",IF(A3="MSE","MSE",IF(A3="ESE","ESE","L"&A3)))) -> L0 | C3: =IF($A$1="","",IF(Setup!B2="","","Course delivery plan, Course assessment plan, Course outcomes, Program outcomes, CO-PO mapping, reference books.")) -> Course delivery plan, Course assessment plan, Course outcomes, Program outcomes, CO-PO mapping, reference books. | D3: =IF(A3="","","---") -> --- | F3: {=_xlfn._xlws.FILTER(Setup!$C$3:$C$7,Setup!$C$3:$C$7<>"","")} -> CO1 | G3: {=IF(F3="","",_xlfn.XLOOKUP(Setup!$B$7&Setup!$B$8&F3,COs!$A$2:$A$1000&COs!$C$2:$C$1000&COs!$E$2:$E$1000,COs!$G$2:$G$1000,""))} -> 10 | H3: =IF(F3="","",G3-COUNTIF('Lesson Plan - Sort'!$D$3:$D$50,F3)) -> 0
A4: =IF(C4="","",IF(C4="MID SEMESTER EXAM","MSE",1)) -> 1 | B4: =IF(A4="","",IF(A4="MSE","MSE",IF(A4="ESE","ESE","L"&A4))) -> L1 | C4: Conceptual introduction to vector spaces and vector operations. Scalar product. | D4: CO1 | F4: CO2 | G4: {=IF(F4="","",_xlfn.XLOOKUP(Setup!$B$7&Setup!$B$8&F4,COs!$A$2:$A$1000&COs!$C$2:$C$1000&COs!$E$2:$E$1000,COs!$G$2:$G$1000,""))} -> 14 | H4: =IF(F4="","",G4-COUNTIF('Lesson Plan - Sort'!$D$3:$D$50,F4)) -> 0
A5: =IF(C5="","",IF(C5="MID SEMESTER EXAM","MSE",IF(C5="END SEMESTER EXAM","ESE",IFERROR(A4+1,A3+1)))) -> 2 | B5: =IF(A5="","",IF(A5="MSE","MSE",IF(A5="ESE","ESE","L"&A5))) -> L2 | C5: Introduction to matrices. Types of matrices. Operations. Matric-vector multiplication. | D5: CO2 | F5: CO3 | G5: {=IF(F5="","",_xlfn.XLOOKUP(Setup!$B$7&Setup!$B$8&F5,COs!$A$2:$A$1000&COs!$C$2:$C$1000&COs!$E$2:$E$1000,COs!$G$2:$G$1000,""))} -> 12 | H5: =IF(F5="","",G5-COUNTIF('Lesson Plan - Sort'!$D$3:$D$50,F5)) -> 0
A6: =IF(C6="","",IF(C6="MID SEMESTER EXAM","MSE",IF(C6="END SEMESTER EXAM","ESE",IFERROR(A5+1,A4+1)))) -> 3 | B6: =IF(A6="","",IF(A6="MSE","MSE",IF(A6="ESE","ESE","L"&A6))) -> L3 | C6: Inner and outer products. Norm of a vector. Distance - standard deviation. Standardizations versus normalization. | D6: CO1 | G6: {=IF(F6="","",_xlfn.XLOOKUP(Setup!$B$7&Setup!$B$8&F6,COs!$A$2:$A$1000&COs!$C$2:$C$1000&COs!$E$2:$E$1000,COs!$G$2:$G$1000,""))} | H6: =IF(F6="","",G6-COUNTIF('Lesson Plan - Sort'!$D$3:$D$50,F6))
A7: =IF(C7="","",IF(C7="MID SEMESTER EXAM","MSE",IF(C7="END SEMESTER EXAM","ESE",IFERROR(A6+1,A5+1)))) -> 4 | B7: =IF(A7="","",IF(A7="MSE","MSE",IF(A7="ESE","ESE","L"&A7))) -> L4 | C7: Linear independence and basis vectors. | D7: CO2 | G7: {=IF(F7="","",_xlfn.XLOOKUP(Setup!$B$7&Setup!$B$8&F7,COs!$A$2:$A$1000&COs!$C$2:$C$1000&COs!$E$2:$E$1000,COs!$G$2:$G$1000,""))} | H7: =IF(F7="","",G7-COUNTIF('Lesson Plan - Sort'!$D$3:$D$50,F7))
A8: =IF(C8="","",IF(C8="MID SEMESTER EXAM","MSE",IF(C8="END SEMESTER EXAM","ESE",IFERROR(A7+1,A6+1)))) -> 5 | B8: =IF(A8="","",IF(A8="MSE","MSE",IF(A8="ESE","ESE","L"&A8))) -> L5 | C8: High-dimensional vector embeddings as in Word2Vec and LLMs. | D8: CO2 | F8: =IF($A$1="","","Total") -> Total | G8: =IF($A$1="","",SUM(G3:G7)) -> 36 | H8: =IF($A$1="","",SUM(H3:H7)) -> 0
